Workbook

Sheet 20221029204422
A1: Variação mensal durante o Plano Real
C2: julho 1994 | D2: agosto 1994 | E2: setembro 1994 | F2: outubro 1994 | G2: novembro 1994 | H2: dezembro 1994 | I2: janeiro 1995 | J2: fevereiro 1995 | K2: março 1995 | L2: abril 1995 | M2: maio 1995 | N2: junho 1995 | O2: julho 1995 | P2: agosto 1995 | Q2: setembro 1995 | R2: outubro 1995 | S2: novembro 1995 | T2: dezembro 1995 | U2: janeiro 1996 | V2: fevereiro 1996 | W2: março 1996 | X2: abril 1996 | Y2: maio 1996 | Z2: junho 1996 | AA2: julho 1996 | AB2: agosto 1996 | AC2: setembro 1996 | AD2: outubro 1996 | AE2: novembro 1996 | AF2: dezembro 1996 | AG2: janeiro 1997 | AH2: fevereiro 1997 | AI2: março 1997 | AJ2: abril 1997 | AK2: maio 1997 | AL2: junho 1997 | AM2: julho 1997 | AN2: agosto 1997 | AO2: setembro 1997 | AP2: outubro 1997 | AQ2: novembro 1997 | AR2: dezembro 1997 | AS2: janeiro 1998 | AT2: fevereiro 1998 | AU2: março 1998 | AV2: abril 1998 | AW2: maio 1998 | AX2: junho 1998 | AY2: julho 1998 | AZ2: agosto 1998 | BA2: setembro 1998 | BB2: outubro 1998 | BC2: novembro 1998 | BD2: dezembro 1998 | BE2: janeiro 1999 | BF2: fevereiro 1999 | BG2: março 1999 | BH2: abril 1999 | BI2: maio 1999 | BJ2: junho 1999 | BK2: julho 1999 | BL2: agosto 1999 | BM2: setembro 1999 | BN2: outubro 1999 | BO2: novembro 1999 | BP2: dezembro 1999 | BQ2: janeiro 2000 | BR2: fevereiro 2000 | BS2: março 2000 | BT2: abril 2000 | BU2: maio 2000 | BV2: junho 2000 | BW2: julho 2000 | BX2: agosto 2000 | BY2: setembro 2000 | BZ2: outubro 2000 | CA2: novembro 2000 | CB2: dezembro 2000 | CC2: janeiro 2001 | CD2: fevereiro 2001 | CE2: março 2001 | CF2: abril 2001 | CG2: maio 2001 | CH2: junho 2001 | CI2: julho 2001 | CJ2: agosto 2001 | CK2: setembro 2001 | CL2: outubro 2001 | CM2: novembro 2001 | CN2: dezembro 2001 | CO2: janeiro 2002 | CP2: fevereiro 2002 | CQ2: março 2002 | CR2: abril 2002 | CS2: maio 2002 | CT2: junho 2002 | CU2: julho 2002 | CV2: agosto 2002 | CW2: setembro 2002 | CX2: outubro 2002 | CY2: novembro 2002 | CZ2: dezembro 2002 | DA2: janeiro 2003 | DB2: fevereiro 2003 | DC2: março 2003 | DD2: abril 2003 | DE2: maio 2003 | DF2: junho 2003 | DG2: julho 2003 | DH2: agosto 2003 | DI2: setembro 2003 | DJ2: outubro 2003 | DK2: novembro 2003 | DL2: dezembro 2003 | DM2: janeiro 2004 | DN2: fevereiro 2004 | DO2: março 2004 | DP2: abril 2004 | DQ2: maio 2004 | DR2: junho 2004 | DS2: julho 2004 | DT2: agosto 2004 | DU2: setembro 2004 | DV2: outubro 2004 | DW2: novembro 2004 | DX2: dezembro 2004 | DY2: janeiro 2005 | DZ2: fevereiro 2005 | EA2: março 2005 | EB2: abril 2005 | EC2: maio 2005 | ED2: junho 2005 | EE2: julho 2005 | EF2: agosto 2005 | EG2: setembro 2005 | EH2: outubro 2005 | EI2: novembro 2005 | EJ2: dezembro 2005 | EK2: janeiro 2006 | EL2: fevereiro 2006 | EM2: março 2006 | EN2: abril 2006 | EO2: maio 2006 | EP2: junho 2006 | EQ2: julho 2006 | ER2: agosto 2006 | ES2: setembro 2006 | ET2: outubro 2006 | EU2: novembro 2006 | EV2: dezembro 2006 | EW2: janeiro 2007 | EX2: fevereiro 2007 | EY2: março 2007 | EZ2: abril 2007 | FA2: maio 2007 | FB2: junho 2007 | FC2: julho 2007 | FD2: agosto 2007 | FE2: setembro 2007 | FF2: outubro 2007 | FG2: novembro 2007 | FH2: dezembro 2007 | FI2: janeiro 2008 | FJ2: fevereiro 2008 | FK2: março 2008 | FL2: abril 2008 | FM2: maio 2008 | FN2: junho 2008 | FO2: julho 2008 | FP2: agosto 2008 | FQ2: setembro 2008 | FR2: outubro 2008 | FS2: novembro 2008 | FT2: dezembro 2008 | FU2: janeiro 2009 | FV2: fevereiro 2009 | FW2: março 2009 | FX2: abril 2009 | FY2: maio 2009 | FZ2: junho 2009 | GA2: julho 2009 | GB2: agosto 2009 | GC2: setembro 2009 | GD2: outubro 2009 | GE2: novembro 2009 | GF2: dezembro 2009 | GG2: janeiro 2010 | GH2: fevereiro 2010 | GI2: março 2010 | GJ2: abril 2010 | GK2: maio 2010 | GL2: junho 2010 | GM2: julho 2010 | GN2: agosto 2010 | GO2: setembro 2010 | GP2: outubro 2010 | GQ2: novembro 2010 | GR2: dezembro 2010 | GS2: janeiro 2011 | GT2: fevereiro 2011 | GU2: março 2011 | GV2: abril 2011 | GW2: maio 2011 | GX2: junho 2011 | GY2: julho 2011 | GZ2: agosto 2011 | HA2: setembro 2011 | HB2: outubro 2011 | HC2: novembro 2011 | HD2: dezembro 2011 | HE2: janeiro 2012 | HF2: fevereiro 2012 | HG2: março 2012 | HH2: abril 2012 | HI2: maio 2012 | HJ2: junho 2012 | HK2: julho 2012 | HL2: agosto 2012 | HM2: setembro 2012 | HN2: outubro 2012 | HO2: novembro 2012 | HP2: dezembro 2012 | HQ2: janeiro 2013 | HR2: fevereiro 2013 | HS2: março 2013 | HT2: abril 2013 | HU2: maio 2013 | HV2: junho 2013 | HW2: julho 2013 | HX2: agosto 2013 | HY2: setembro 2013 | HZ2: outubro 2013 | IA2: novembro 2013 | IB2: dezembro 2013 | IC2: janeiro 2014 | ID2: fevereiro 2014 | IE2: março 2014 | IF2: abril 2014 | IG2: maio 2014 | IH2: junho 2014 | II2: julho 2014 | IJ2: agosto 2014 | IK2: setembro 2014 | IL2: outubro 2014 | IM2: novembro 2014 | IN2: dezembro 2014 | IO2: janeiro 2015 | IP2: fevereiro 2015 | IQ2: março 2015 | IR2: abril 2015 | IS2: maio 2015 | IT2: junho 2015 | IU2: julho 2015 | IV2: agosto 2015 | IW2: setembro 2015 | IX2: outubro 2015 | IY2: novembro 2015 | IZ2: dezembro 2015 | JA2: janeiro 2016 | JB2: fevereiro 2016 | JC2: março 2016 | JD2: abril 2016 | JE2: maio 2016 | JF2: junho 2016 | JG2: julho 2016 | JH2: agosto 2016 | JI2: setembro 2016 | JJ2: outubro 2016 | JK2: novembro 2016 | JL2: dezembro 2016 | JM2: janeiro 2017 | JN2: fevereiro 2017 | JO2: março 2017 | JP2: abril 2017 | JQ2: maio 2017 | JR2: junho 2017 | JS2: julho 2017 | JT2: agosto 2017 | JU2: setembro 2017 | JV2: outubro 2017 | JW2: novembro 2017 | JX2: dezembro 2017 | JY2: janeiro 2018 | JZ2: fevereiro 2018 | KA2: março 2018 | KB2: abril 2018 | KC2: maio 2018 | KD2: junho 2018 | KE2: julho 2018 | KF2: agosto 2018 | KG2: setembro 2018 | KH2: outubro 2018 | KI2: novembro 2018 | KJ2: dezembro 2018 | KK2: janeiro 2019 | KL2: fevereiro 2019 | KM2: março 2019 | KN2: abril 2019 | KO2: maio 2019 | KP2: junho 2019 | KQ2: julho 2019 | KR2: agosto 2019 | KS2: setembro 2019 | KT2: outubro 2019 | KU2: novembro 2019 | KV2: dezembro 2019 | KW2: janeiro 2020 | KX2: fevereiro 2020 | KY2: março 2020 | KZ2: abril 2020 | LA2: maio 2020 | LB2: junho 2020 | LC2: julho 2020 | LD2: agosto 2020 | LE2: setembro 2020 | LF2: outubro 2020 | LG2: novembro 2020 | LH2: dezembro 2020 | LI2: janeiro 2021 | LJ2: fevereiro 2021 | LK2: março 2021 | LL2: abril 2021 | LM2: maio 2021 | LN2: junho 2021 | LO2: julho 2021 | LP2: agosto 2021 | LQ2: setembro 2021 | LR2: outubro 2021 | LS2: novembro 2021 | LT2: dezembro 2021 | LU2: janeiro 2022 | LV2: fevereiro 2022 | LW2: março 2022 | LX2: abril 2022 | LY2: maio 2022 | LZ2: junho 2022 | MA2: julho 2022 | MB2: agosto 2022 | MC2: setembro 2022
A4: Brasil | C4: 6,84 | D4: 1,86 | E4: 1,53 | F4: 2,62 | G4: 2,81 | H4: 1,71 | I4: 1,70 | J4: 1,02 | K4: 1,55 | L4: 2,43 | M4: 2,67 | N4: 2,26 | O4: 2,36 | P4: 0,99 | Q4: 0,99 | R4: 1,41 | S4: 1,47 | T4: 1,56 | U4: 1,34 | V4: 1,03 | W4: 0,35 | X4: 1,26 | Y4: 1,22 | Z4: 1,19 | AA4: 1,11 | AB4: 0,44 | AC4: 0,15 | AD4: 0,30 | AE4: 0,32 | AF4: 0,47 | AG4: 1,18 | AH4: 0,50 | AI4: 0,51 | AJ4: 0,88 | AK4: 0,41 | AL4: 0,54 | AM4: 0,22 | AN4: -0,02 | AO4: 0,06 | AP4: 0,23 | AQ4: 0,17 | AR4: 0,43 | AS4: 0,71 | AT4: 0,46 | AU4: 0,34 | AV4: 0,24 | AW4: 0,50 | AX4: 0,02 | AY4: -0,12 | AZ4: -0,51 | BA4: -0,22 | BB4: 0,02 | BC4: -0,12 | BD4: 0,33 | BE4: 0,70 | BF4: 1,05 | BG4: 1,10 | BH4: 0,56 | BI4: 0,30 | BJ4: 0,19 | BK4: 1,09 | BL4: 0,56 | BM4: 0,31 | BN4: 1,19 | BO4: 0,95 | BP4: 0,60 | BQ4: 0,62 | BR4: 0,13 | BS4: 0,22 | BT4: 0,42 | BU4: 0,01 | BV4: 0,23 | BW4: 1,61 | BX4: 1,31 | BY4: 0,23 | BZ4: 0,14 | CA4: 0,32 | CB4: 0,59 | CC4: 0,57 | CD4: 0,46 | CE4: 0,38 | CF4: 0,58 | CG4: 0,41 | CH4: 0,52 | CI4: 1,33 | CJ4: 0,70 | CK4: 0,28 | CL4: 0,83 | CM4: 0,71 | CN4: 0,65 | CO4: 0,52 | CP4: 0,36 | CQ4: 0,60 | CR4: 0,80 | CS4: 0,21 | CT4: 0,42 | CU4: 1,19 | CV4: 0,65 | CW4: 0,72 | CX4: 1,31 | CY4: 3,02 | CZ4: 2,10 | DA4: 2,25 | DB4: 1,57 | DC4: 1,23 | DD4: 0,97 | DE4: 0,61 | DF4: -0,15 | DG4: 0,20 | DH4: 0,34 | DI4: 0,78 | DJ4: 0,29 | DK4: 0,34 | DL4: 0,52 | DM4: 0,76 | DN4: 0,61 | DO4: 0,47 | DP4: 0,37 | DQ4: 0,51 | DR4: 0,71 | DS4: 0,91 | DT4: 0,69 | DU4: 0,33 | DV4: 0,44 | DW4: 0,69 | DX4: 0,86 | DY4: 0,58 | DZ4: 0,59 | EA4: 0,61 | EB4: 0,87 | EC4: 0,49 | ED4: -0,02 | EE4: 0,25 | EF4: 0,17 | EG4: 0,35 | EH4: 0,75 | EI4: 0,55 | EJ4: 0,36 | EK4: 0,59 | EL4: 0,41 | EM4: 0,43 | EN4: 0,21 | EO4: 0,10 | EP4: -0,21 | EQ4: 0,19 | ER4: 0,05 | ES4: 0,21 | ET4: 0,33 | EU4: 0,31 | EV4: 0,48 | EW4: 0,44 | EX4: 0,44 | EY4: 0,37 | EZ4: 0,25 | FA4: 0,28 | FB4: 0,28 | FC4: 0,24 | FD4: 0,47 | FE4: 0,18 | FF4: 0,30 | FG4: 0,38 | FH4: 0,74 | FI4: 0,54 | FJ4: 0,49 | FK4: 0,48 | FL4: 0,55 | FM4: 0,79 | FN4: 0,74 | FO4: 0,53 | FP4: 0,28 | FQ4: 0,26 | FR4: 0,45 | FS4: 0,36 | FT4: 0,28 | FU4: 0,48 | FV4: 0,55 | FW4: 0,20 | FX4: 0,48 | FY4: 0,47 | FZ4: 0,36 | GA4: 0,24 | GB4: 0,15 | GC4: 0,24 | GD4: 0,28 | GE4: 0,41 | GF4: 0,37 | GG4: 0,75 | GH4: 0,78 | GI4: 0,52 | GJ4: 0,57 | GK4: 0,43 | GL4: 0,00 | GM4: 0,01 | GN4: 0,04 | GO4: 0,45 | GP4: 0,75 | GQ4: 0,83 | GR4: 0,63 | GS4: 0,83 | GT4: 0,80 | GU4: 0,79 | GV4: 0,77 | GW4: 0,47 | GX4: 0,15 | GY4: 0,16 | GZ4: 0,37 | HA4: 0,53 | HB4: 0,43 | HC4: 0,52 | HD4: 0,50 | HE4: 0,56 | HF4: 0,45 | HG4: 0,21 | HH4: 0,64 | HI4: 0,36 | HJ4: 0,08 | HK4: 0,43 | HL4: 0,41 | HM4: 0,57 | HN4: 0,59 | HO4: 0,60 | HP4: 0,79 | HQ4: 0,86 | HR4: 0,60 | HS4: 0,47 | HT4: 0,55 | HU4: 0,37 | HV4: 0,26 | HW4: 0,03 | HX4: 0,24 | HY4: 0,35 | HZ4: 0,57 | IA4: 0,54 | IB4: 0,92 | IC4: 0,55 | ID4: 0,69 | IE4: 0,92 | IF4: 0,67 | IG4: 0,46 | IH4: 0,40 | II4: 0,01 | IJ4: 0,25 | IK4: 0,57 | IL4: 0,42 | IM4: 0,51 | IN4: 0,78 | IO4: 1,24 | IP4: 1,22 | IQ4: 1,32 | IR4: 0,71 | IS4: 0,74 | IT4: 0,79 | IU4: 0,62 | IV4: 0,22 | IW4: 0,54 | IX4: 0,82 | IY4: 1,01 | IZ4: 0,96 | JA4: 1,27 | JB4: 0,90 | JC4: 0,43 | JD4: 0,61 | JE4: 0,78 | JF4: 0,35 | JG4: 0,52 | JH4: 0,44 | JI4: 0,08 | JJ4: 0,26 | JK4: 0,18 | JL4: 0,30 | JM4: 0,38 | JN4: 0,33 | JO4: 0,25 | JP4: 0,14 | JQ4: 0,31 | JR4: -0,23 | JS4: 0,24 | JT4: 0,19 | JU4: 0,16 | JV4: 0,42 | JW4: 0,28 | JX4: 0,44 | JY4: 0,29 | JZ4: 0,32 | KA4: 0,09 | KB4: 0,22 | KC4: 0,40 | KD4: 1,26 | KE4: 0,33 | KF4: -0,09 | KG4: 0,48 | KH4: 0,45 | KI4: -0,21 | KJ4: 0,15 | KK4: 0,32 | KL4: 0,43 | KM4: 0,75 | KN4: 0,57 | KO4: 0,13 | KP4: 0,01 | KQ4: 0,19 | KR4: 0,11 | KS4: -0,04 | KT4: 0,10 | KU4: 0,51 | KV4: 1,15 | KW4: 0,21 | KX4: 0,25 | KY4: 0,07 | KZ4: -0,31 | LA4: -0,38 | LB4: 0,26 | LC4: 0,36 | LD4: 0,24 | LE4: 0,64 | LF4: 0,86 | LG4: 0,89 | LH4: 1,35 | LI4: 0,25 | LJ4: 0,86 | LK4: 0,93 | LL4: 0,31 | LM4: 0,83 | LN4: 0,53 | LO4: 0,96 | LP4: 0,87 | LQ4: 1,16 | LR4: 1,25 | LS4: 0,95 | LT4: 0,73 | LU4: 0,54 | LV4: 1,01 | LW4: 1,62 | LX4: 1,06 | LY4: 0,47 | LZ4: 0,67 | MA4: -0,68 | MB4: -0,36 | MC4: -0,29
A6: Fonte: "IBGE - Índice Nacional de Preços ao Consumidor Amplo"

Sheet Planilha3
A1: Mês | B1: Mediana das previsões (%) | C1: Peso - anual (%) | D1: Peso - período (%)
A2: 43490 | B2: 0.42 | C2: =B2/B14 -> 0.099526066 | D2: =B2/D14 -> 0.12923077
A3: 43518 | B3: 0.33 | C3: =B3/B14 -> 0.078199052 | D3: =B3/D14 -> 0.10153846
A4: 43553 | B4: 0.5 | C4: =B4/B14 -> 0.11848341 | D4: =B4/D14 -> 0.15384615
A5: 43581 | B5: 0.56 | C5: =B5/B14 -> 0.13270142 | D5: =B5/D14 -> 0.17230769
A6: 43616 | B6: 0.26 | C6: =B6/B14 -> 0.061611374
A7: 43644 | B7: 0.24 | C7: =B7/B14 -> 0.056872038
A8: 43672 | B8: 0.22 | C8: =B8/B14 -> 0.052132701
A9: 43707 | B9: 0.11 | C9: =B9/B14 -> 0.026066351
A10: 43735 | B10: 0.06 | C10: =B10/B14 -> 0.014218009
A11: 43767 | B11: 0.08 | C11: =B11/B14 -> 0.018957346
A12: 43798 | B12: 0.47 | C12: =B12/B14 -> 0.11137441 | D12: =B12/D14 -> 0.14461538
A13: 43826 | B13: 0.97 | C13: =B13/B14 -> 0.22985782 | D13: =B13/D14 -> 0.29846154
A14: TOTAL | B14: =SUM(B2:B13) -> 4.22 | C14: Semitotal | D14: =B2+B3+B4+B5+B12+B13 -> 3.25

Sheet Planilha2
A1: mês/ano | B1: variação mensal (%) | C1: 1+i | D1: Acumulado | G1: Taxa pré-fixado | H1: Período (dias) | I1: Taxa (%)
A2: 43009 | B2: 0,42 | C2: =1+B2/100 -> 1.0042 | D2: 1.0042 | G2: 13.7841 | H2: 125 | I2: =(((1+G2/100)^(1/252))^H2-1)*100 -> 6.6149833
A3: 43040 | B3: 0,28 | C3: =1+B3/100 -> 1.0028 | D3: =C3*D2 -> 1.0070118
A4: 43070 | B4: 0,44 | C4: =1+B4/100 -> 1.0044 | D4: =C4*D3 -> 1.0114426 | G4: Preço | H4: VNA | I4: Inflação no período
A5: 43101 | B5: 0,29 | C5: =1+B5/100 -> 1.0029 | D5: =C5*D4 -> 1.0143758 | G5: 4067.3786 | H5: 3953.2138 | I5: =((G5*(1+I2/100))/(H5*(1+2.956301/100))-1)*100 -> 6.5441516
A6: 43132 | B6: 0,32 | C6: =1+B6/100 -> 1.0032 | D6: =C6*D5 -> 1.0176218
A7: 43160 | B7: 0,09 | C7: =1+B7/100 -> 1.0009 | D7: =C7*D6 -> 1.0185377 | G7: Inflação (outubro 2022-3)
A8: 43191 | B8: 0,22 | C8: =1+B8/100 -> 1.0022 | D8: =C8*D7 -> 1.0207784 | G8: 6.735
A9: 43221 | B9: 0,40 | C9: =1+B9/100 -> 1.004 | D9: =C9*D8 -> 1.0248616 | G9: Inflação (outubro 2023-4)
A10: 43252 | B10: 1,26 | C10: =1+B10/100 -> 1.0126 | D10: =C10*D9 -> 1.0377748 | G10: 5.9937
A11: 43282 | B11: 0,33 | C11: =1+B11/100 -> 1.0033 | D11: =C11*D10 -> 1.0411995 | G11: Inflação (outubro 2024-5)
A12: 43313 | B12: -0,09 | C12: =1+B12/100 -> 0.9991 | D12: =C12*D11 -> 1.0402624 | G12: 5.8136
A13: 43344 | B13: 0,48 | C13: =1+B13/100 -> 1.0048 | D13: =C13*D12 -> 1.0452556 | G13: Inflação (outubro 2025-6)
A14: 43374 | B14: 0,45 | C14: =1+B14/100 -> 1.0045 | D14: =C14*D13 -> 1.0499593 | G14: 5.8076
A15: 43405 | B15: -0,21 | C15: =1+B15/100 -> 0.9979 | D15: =C15*D14 -> 1.0477544 | G15: Inflação (outubro 2026-7)
A16: 43435 | B16: 0,15 | C16: =1+B16/100 -> 1.0015 | D16: =C16*D15 -> 1.049326 | G16: 5.8405
A17: 43466 | B17: 0,32 | C17: =1+B17/100 -> 1.0032 | D17: =C17*D16 -> 1.0526839 | G17: Inflação (outubro 2027-8)
A18: 43497 | B18: 0,43 | C18: =1+B18/100 -> 1.0043 | D18: =C18*D17 -> 1.0572104 | G18: 5.8763
A19: 43525 | B19: 0,75 | C19: =1+B19/100 -> 1.0075 | D19: =C19*D18 -> 1.0651395 | G19: Inflação (outubro 2028-9)
A20: 43556 | B20: 0,57 | C20: =1+B20/100 -> 1.0057 | D20: =C20*D19 -> 1.0712108 | G20: 5.9072
A21: 43586 | B21: 0,13 | C21: =1+B21/100 -> 1.0013 | D21: =C21*D20 -> 1.0726033 | G21: Inflação (outubro 2029-30)
A22: 43617 | B22: 0,01 | C22: =1+B22/100 -> 1.0001 | D22: =C22*D21 -> 1.0727106 | G22: 5.9321
A23: 43647 | B23: 0,19 | C23: =1+B23/100 -> 1.0019 | D23: =C23*D22 -> 1.0747488 | G23: Inflação (outubro 2030-1)
A24: 43678 | B24: 0,11 | C24: =1+B24/100 -> 1.0011 | D24: =C24*D23 -> 1.075931 | G24: 5.9525
A25: 43709 | B25: -0,04 | C25: =1+B25/100 -> 0.9996 | D25: =C25*D24 -> 1.0755006 | G25: Inflação (outubro 2031-2)
A26: 43739 | B26: 0,10 | C26: =1+B26/100 -> 1.001 | D26: =C26*D25 -> 1.0765761 | G26: 5.969
A27: 43770 | B27: 0,51 | C27: =1+B27/100 -> 1.0051 | D27: =C27*D26 -> 1.0820666 | G27: Inflação (outubro 2032-3)
A28: 43800 | B28: 1,15 | C28: =1+B28/100 -> 1.0115 | D28: =C28*D27 -> 1.0945104 | G28: 5.982487
A29: 43831 | B29: 0,21 | C29: =1+B29/100 -> 1.0021 | D29: =C29*D28 -> 1.0968089 | G29: Inflação (outubro 2033-4)
A30: 43862 | B30: 0,25 | C30: =1+B30/100 -> 1.0025 | D30: =C30*D29 -> 1.0995509 | G30: 5.993872
A31: 43891 | B31: 0,07 | C31: =1+B31/100 -> 1.0007 | D31: =C31*D30 -> 1.1003206 | G31: Inflação (outubro 2034-5)
A32: 43922 | B32: -0,31 | C32: =1+B32/100 -> 0.9969 | D32: =C32*D31 -> 1.0969096 | G32: 6.003517
A33: 43952 | B33: -0,38 | C33: =1+B33/100 -> 0.9962 | D33: =C33*D32 -> 1.0927413 | G33: Inflação (outubro 2035-6)
A34: 43983 | B34: 0,26 | C34: =1+B34/100 -> 1.0026 | D34: =C34*D33 -> 1.0955825 | G34: 6.011789
A35: 44013 | B35: 0,36 | C35: =1+B35/100 -> 1.0036 | D35: =C35*D34 -> 1.0995266 | G35: Inflação (outubro 2036-7)
A36: 44044 | B36: 0,24 | C36: =1+B36/100 -> 1.0024 | D36: =C36*D35 -> 1.1021654 | G36: 6.018959
A37: 44075 | B37: 0,64 | C37: =1+B37/100 -> 1.0064 | D37: =C37*D36 -> 1.1092193 | G37: Inflação (outubro 2037-8)
A38: 44105 | B38: 0,86 | C38: =1+B38/100 -> 1.0086 | D38: =C38*D37 -> 1.1187586 | G38: 6.025232
A39: 44136 | B39: 0,89 | C39: =1+B39/100 -> 1.0089 | D39: =C39*D38 -> 1.1287155 | G39: Inflação (outubro 2038-9)
A40: 44166 | B40: 1,35 | C40: =1+B40/100 -> 1.0135 | D40: =C40*D39 -> 1.1439532 | G40: 6.030767
...

Sheet Planilha4
A1: 1 | B1: 0.03085256 | C1: =1000*B1 -> 30.85256 | D1: =A1*C1 -> 30.85256 | E1: =(1+B1)^(-A1) -> 0.97007083 | F1: =D1*E1 -> 29.929169
A2: 2 | B2: 0.03085256 | C2: =1000*B2 -> 30.85256 | D2: =A2*C2 -> 61.70512 | E2: =(1+B2)^(-A2) -> 0.94103742 | F2: =D2*E2 -> 58.066827
A3: 3 | B3: 0.03085256 | C3: =1000*B3 -> 30.85256 | D3: =A3*C3 -> 92.55768 | E3: =(1+B3)^(-A3) -> 0.91287295 | F3: =D3*E3 -> 84.493402
A4: 4 | B4: 0.03085256 | C4: =1000*B4 -> 30.85256 | D4: =A4*C4 -> 123.41024 | E4: =(1+B4)^(-A4) -> 0.88555142 | F4: =D4*E4 -> 109.28611
A5: 5 | B5: 0.03085256 | C5: =1000*B5 -> 30.85256 | D5: =A5*C5 -> 154.2628 | E5: =(1+B5)^(-A5) -> 0.8590476 | F5: =D5*E5 -> 132.51909
A6: 6 | B6: 0.03085256 | C6: =1000*B6 -> 30.85256 | D6: =A6*C6 -> 185.11536 | E6: =(1+B6)^(-A6) -> 0.83333702 | F6: =D6*E6 -> 154.26348
A7: 7 | B7: 0.03085256 | C7: =1000*B7 -> 30.85256 | D7: =A7*C7 -> 215.96792 | E7: =(1+B7)^(-A7) -> 0.80839594 | F7: =D7*E7 -> 174.58759
A8: 8 | B8: 0.03085256 | C8: =1000*B8 -> 30.85256 | D8: =A8*C8 -> 246.82048 | E8: =(1+B8)^(-A8) -> 0.78420132 | F8: =D8*E8 -> 193.55695
A9: 9 | B9: 0.03085256 | C9: =1000*B9 -> 30.85256 | D9: =A9*C9 -> 277.67304 | E9: =(1+B9)^(-A9) -> 0.76073083 | F9: =D9*E9 -> 211.23444
A10: 10 | B10: 0.03085256 | C10: =1000*B10 -> 30.85256 | D10: =A10*C10 -> 308.5256 | E10: =(1+B10)^(-A10) -> 0.73796279 | F10: =D10*E10 -> 227.68041
A11: 11 | B11: 0.03085256 | C11: =1000*B11 -> 30.85256 | D11: =A11*C11 -> 339.37816 | E11: =(1+B11)^(-A11) -> 0.71587617 | F11: =D11*E11 -> 242.95274
A12: 12 | B12: 0.03085256 | C12: =1000*B12 -> 30.85256 | D12: =A12*C12 -> 370.23072 | E12: =(1+B12)^(-A12) -> 0.6944506 | F12: =D12*E12 -> 257.10694
... A23: 23 | B23: 0.03085256 | C23: =1000*B23 -> 30.85256 | D23: =A23*C23 -> 709.60888 | E23: =(1+B23)^(-A23) -> 0.49714064 | F23: =D23*E23 -> 352.77541
E24: cupom | F24: =SUM(F1:F23) -> 5367.4137
E25: principal | F25: =(A23*1000)*E23 -> 11434.235
E26: numerador | F26: =F24+F25 -> 16801.648
E27: duração | F27: =(F26/1000)/2 -> 8.4008242
