Workbook

Sheet Planilha1

Sheet Planilha2
A1: Year | B1: Performance | C1: Social | D1: Sustainable | E1: Transition | F1: Green
A2: 2015 | B2: 0 | C2: 0 | D2: 0 | E2: 0 | F2: 1
A3: 2016 | B3: 0 | C3: 0 | D3: 0 | E3: 0 | F3: 3
A4: 2017 | B4: 0 | C4: 0 | D4: 0 | E4: 0 | F4: 9
A5: 2018 | B5: 0 | C5: 1 | D5: 0 | E5: 0 | F5: 3
A6: 2019 | B6: 3 | C6: 0 | D6: 0 | E6: 1 | F6: 15
A7: 2020 | B7: 8 | C7: 2 | D7: 5 | E7: 2 | F7: 21
A8: 2021 | B8: 13 | C8: 0 | D8: 3 | E8: 0 | F8: 18

Sheet Planilha3
A1: year | B1: category | C1: value | D1: value_r
A2: 2015 | B2: Performance | C2: =0 -> 0 | D2: {=C2/_xlfn._xlws.FILTER(Planilha9!$D$2:$D$8,(Planilha9!$A$2:$A$8)=A2)} -> 0
A3: 2015 | B3: Social | C3: =0 -> 0 | D3: {=C3/_xlfn._xlws.FILTER(Planilha9!$D$2:$D$8,(Planilha9!$A$2:$A$8)=A3)} -> 0
A4: 2015 | B4: Sustainable | C4: =0 -> 0 | D4: {=C4/_xlfn._xlws.FILTER(Planilha9!$D$2:$D$8,(Planilha9!$A$2:$A$8)=A4)} -> 0
A5: 2015 | B5: Transition | C5: =0 -> 0 | D5: {=C5/_xlfn._xlws.FILTER(Planilha9!$D$2:$D$8,(Planilha9!$A$2:$A$8)=A5)} -> 0
A6: 2015 | B6: Green | C6: =549.45/1000 -> 0.54945 | D6: {=C6/_xlfn._xlws.FILTER(Planilha9!$D$2:$D$8,(Planilha9!$A$2:$A$8)=A6)} -> 0.54945
A7: 2016 | B7: Performance | C7: =0 -> 0 | D7: {=C7/_xlfn._xlws.FILTER(Planilha9!$D$2:$D$8,(Planilha9!$A$2:$A$8)=A7)} -> 0
A8: 2016 | B8: Social | C8: =0 -> 0 | D8: {=C8/_xlfn._xlws.FILTER(Planilha9!$D$2:$D$8,(Planilha9!$A$2:$A$8)=A8)} -> 0
A9: 2016 | B9: Sustainable | C9: =0 -> 0 | D9: {=C9/_xlfn._xlws.FILTER(Planilha9!$D$2:$D$8,(Planilha9!$A$2:$A$8)=A9)} -> 0
A10: 2016 | B10: Transition | C10: =0 -> 0 | D10: {=C10/_xlfn._xlws.FILTER(Planilha9!$D$2:$D$8,(Planilha9!$A$2:$A$8)=A10)} -> 0
A11: 2016 | B11: Green | C11: =(700+61.6+291.77)/1000 -> 1.05337 | D11: {=C11/_xlfn._xlws.FILTER(Planilha9!$D$2:$D$8,(Planilha9!$A$2:$A$8)=A11)} -> 1.0446462
A12: 2017 | B12: Performance | C12: =0 -> 0 | D12: {=C12/_xlfn._xlws.FILTER(Planilha9!$D$2:$D$8,(Planilha9!$A$2:$A$8)=A12)} -> 0
A13: 2017 | B13: Social | C13: =0 -> 0 | D13: {=C13/_xlfn._xlws.FILTER(Planilha9!$D$2:$D$8,(Planilha9!$A$2:$A$8)=A13)} -> 0
A14: 2017 | B14: Sustainable | C14: =0 -> 0 | D14: {=C14/_xlfn._xlws.FILTER(Planilha9!$D$2:$D$8,(Planilha9!$A$2:$A$8)=A14)} -> 0
A15: 2017 | B15: Transition | C15: =0 -> 0 | D15: {=C15/_xlfn._xlws.FILTER(Planilha9!$D$2:$D$8,(Planilha9!$A$2:$A$8)=A15)} -> 0
A16: 2017 | B16: Green | C16: =(700+13.28+1000+34.06+500+69.62+14.67+3.39+3.24)/1000 -> 2.33826 | D16: {=C16/_xlfn._xlws.FILTER(Planilha9!$D$2:$D$8,(Planilha9!$A$2:$A$8)=A16)} -> 2.2796855
A17: 2018 | B17: Performance | C17: =0 -> 0 | D17: {=C17/_xlfn._xlws.FILTER(Planilha9!$D$2:$D$8,(Planilha9!$A$2:$A$8)=A17)} -> 0
A18: 2018 | B18: Social | C18: =1.51/1000 -> 0.00151 | D18: {=C18/_xlfn._xlws.FILTER(Planilha9!$D$2:$D$8,(Planilha9!$A$2:$A$8)=A18)} -> 0.0014299959
A19: 2018 | B19: Sustainable | C19: =0 -> 0 | D19: {=C19/_xlfn._xlws.FILTER(Planilha9!$D$2:$D$8,(Planilha9!$A$2:$A$8)=A19)} -> 0
A20: 2018 | B20: Transition | C20: =0 -> 0 | D20: {=C20/_xlfn._xlws.FILTER(Planilha9!$D$2:$D$8,(Planilha9!$A$2:$A$8)=A20)} -> 0
A21: 2018 | B21: Green | C21: =(181.28+9.82+31.38)/1000 -> 0.22248 | D21: {=C21/_xlfn._xlws.FILTER(Planilha9!$D$2:$D$8,(Planilha9!$A$2:$A$8)=A21)} -> 0.21069237
A22: 2019 | B22: Performance | C22: =(18.61+250)/1000 -> 0.26861 | D22: {=C22/_xlfn._xlws.FILTER(Planilha9!$D$2:$D$8,(Planilha9!$A$2:$A$8)=A22)} -> 0.24985229
A23: 2019 | B23: Social | C23: =0 -> 0 | D23: {=C23/_xlfn._xlws.FILTER(Planilha9!$D$2:$D$8,(Planilha9!$A$2:$A$8)=A23)} -> 0
A24: 2019 | B24: Sustainable | C24: =0 -> 0 | D24: {=C24/_xlfn._xlws.FILTER(Planilha9!$D$2:$D$8,(Planilha9!$A$2:$A$8)=A24)} -> 0
A25: 2019 | B25: Transition | C25: =500/1000 -> 0.5 | D25: {=C25/_xlfn._xlws.FILTER(Planilha9!$D$2:$D$8,(Planilha9!$A$2:$A$8)=A25)} -> 0.46508374
A26: 2019 | B26: Green | C26: =(213.89+500+52.47+344.52+135.02+10.7+5.28+4.49+9.65+13.18+9.64+98.05+129.92+140.95+73.01)/1000 -> 1.74077 | D26: {=C26/_xlfn._xlws.FILTER(Planilha9!$D$2:$D$8,(Planilha9!$A$2:$A$8)=A26)} -> 1.6192076
A27: 2020 | B27: Performance | C27: =(105+25.63+33.31+750+12.48+32.08+500+194.93)/1000 -> 1.65343 | D27: {=C27/_xlfn._xlws.FILTER(Planilha9!$D$2:$D$8,(Planilha9!$A$2:$A$8)=A27)} -> 1.5229493
A28: 2020 | B28: Social | C28: =(100.38+8.85)/1000 -> 0.10923 | D28: {=C28/_xlfn._xlws.FILTER(Planilha9!$D$2:$D$8,(Planilha9!$A$2:$A$8)=A28)} -> 0.1006101
A29: 2020 | B29: Sustainable | C29: =(48.42+120.27+193.66+0.2+50)/1000 -> 0.41255 | D29: {=C29/_xlfn._xlws.FILTER(Planilha9!$D$2:$D$8,(Planilha9!$A$2:$A$8)=A29)} -> 0.37999355
A30: 2020 | B30: Transition | C30: =(66.65+102.29)/1000 -> 0.16894 | D30: {=C30/_xlfn._xlws.FILTER(Planilha9!$D$2:$D$8,(Planilha9!$A$2:$A$8)=A30)} -> 0.15560807
A31: 2020 | B31: Green | C31: =(200+3.57+59.51+48.54+64.64+50+87.15+54.2+500+305.49+394.51+45.7+4.66+178.89+4.36+50+2.25+28.74+550+233.92+93.57)/1000 -> 2.9597 | D31: {=C31/_xlfn._xlws.FILTER(Planilha9!$D$2:$D$8,(Planilha9!$A$2:$A$8)=A31)} -> 2.7261348
A32: 2021 | B32: Performance | C32: =(500+625+500+1570+81.82+30+82.12+17.86+47.7+1000+400+137.87+137.87)/1000 -> 5.13024 | D32: {=C32/_xlfn._xlws.FILTER(Planilha9!$D$2:$D$8,(Planilha9!$A$2:$A$8)=A32)} -> 4.4847577
A33: 2021 | B33: Social | C33: =0 -> 0 | D33: {=C33/_xlfn._xlws.FILTER(Planilha9!$D$2:$D$8,(Planilha9!$A$2:$A$8)=A33)} -> 0
A34: 2021 | B34: Sustainable | C34: =(500+750+81.82)/1000 -> 1.33182 | D34: {=C34/_xlfn._xlws.FILTER(Planilha9!$D$2:$D$8,(Planilha9!$A$2:$A$8)=A34)} -> 1.1642516
A35: 2021 | B35: Transition | C35: =0 -> 0 | D35: {=C35/_xlfn._xlws.FILTER(Planilha9!$D$2:$D$8,(Planilha9!$A$2:$A$8)=A35)} -> 0
A36: 2021 | B36: Green | C36: =(500+77.46+50+230.77+16.79+121.61+26.46+11.43+190.91+10.91+142.39+64+45.29+26.79+62.11+32.92+25.59+14.71)/1000 -> 1.65014 | D36: {=C36/_xlfn._xlws.FILTER(Planilha9!$D$2:$D$8,(Planilha9!$A$2:$A$8)=A36)} -> 1.4425208

Sheet Planilha4
A1: Year | B1: Bond | C1: Agribusiness Credit Receivable Certificate (CRA) | D1: Real Estate Receivables Certificate (CRI) | E1: Debenture | F1: Infrastructure debentures | G1: Loans | H1: Credit Receivables Investment Funds (FIDC) | I1: Global Notes | J1: Financial Letter | K1: Total
A2: 2015 | B2: =549.45/1000 -> 0.54945 | C2: 0 | D2: 0 | E2: 0 | F2: 0 | G2: 0 | H2: 0 | I2: 0 | J2: 0 | K2: =SUM(Tabela2[[#This Row],[Bond]:[Financial Letter]]) -> 0.54945
A3: 2016 | B3: =700/1000 -> 0.7 | C3: =291.77/1000 -> 0.29177 | D3: =0 -> 0 | E3: =61.6/1000 -> 0.0616 | F3: =0 -> 0 | G3: =0 -> 0 | H3: =0 -> 0 | I3: =0 -> 0 | J3: =0 -> 0 | K3: =SUM(Tabela2[[#This Row],[Bond]:[Financial Letter]]) -> 1.05337
A4: 2017 | B4: =(700+1000+500)/1000 -> 2.2 | C4: =0 -> 0 | D4: =0 -> 0 | E4: =0 -> 0 | F4: =(13.28+34.06+69.62+14.67+3.39+3.24)/1000 -> 0.13826 | G4: =0 -> 0 | H4: =0 -> 0 | I4: =0 -> 0 | J4: =0 -> 0 | K4: =SUM(Tabela2[[#This Row],[Bond]:[Financial Letter]]) -> 2.33826
A5: 2018 | B5: =0 -> 0 | C5: =0 -> 0 | D5: =0 -> 0 | E5: =(1.51+9.82)/1000 -> 0.01133 | F5: =(181.28+31.38)/1000 -> 0.21266 | G5: =0 -> 0 | H5: =0 -> 0 | I5: =0 -> 0 | J5: =0 -> 0 | K5: =SUM(Tabela2[[#This Row],[Bond]:[Financial Letter]]) -> 0.22399
A6: 2019 | B6: =(500+500)/1000 -> 1 | C6: =9.65/1000 -> 0.00965 | D6: =4.49/1000 -> 0.00449 | E6: =(135.02+10.7+5.28+13.18+9.64)/1000 -> 0.17382 | F6: =(213.89+52.47+344.52+98.05+129.92+140.95+73.01)/1000 -> 1.05281 | G6: =(18.61+250)/1000 -> 0.26861 | H6: =0 -> 0 | I6: =0 -> 0 | J6: =0 -> 0 | K6: =SUM(Tabela2[[#This Row],[Bond]:[Financial Letter]]) -> 2.50938
A7: 2020 | B7: =(200+50+500+305.49+394.51+750+500+50+550+50)/1000 -> 3.35 | C7: =(48.54+4.66+28.74+0.2+93.57)/1000 -> 0.17571 | D7: =25.63/1000 -> 0.02563 | E7: =(3.57+8.85+194.93)/1000 -> 0.20735 | F7: =(64.64+87.15+54.2+48.42+120.27+66.65+102.29+193.66)/1000 -> 0.73728 | G7: =(59.51+105+33.31+45.7+12.48+32.08+4.36+2.25)/1000 -> 0.29469 | H7: =0 -> 0 | I7: =0 -> 0 | J7: =(100.38+178.89+233.92)/1000 -> 0.51319 | K7: =SUM(Tabela2[[#This Row],[Bond]:[Financial Letter]]) -> 5.30385
A8: 2021 | B8: =(500+50+500+625+750+500+81.82+1000+400)/1000 -> 4.40682 | C8: =(10.91+142.39+64+45.29+62.11+14.71)/1000 -> 0.33941 | D8: =11.43/1000 -> 0.01143 | E8: =(190.91+81.82+82.12+26.79+47.7+25.59+137.87+137.87)/1000 -> 0.73067 | F8: =(77.46+230.77+121.61)/1000 -> 0.42984 | G8: =(1570+30+26.46+17.86)/1000 -> 1.64432 | H8: =(16.79+32.92)/1000 -> 0.04971 | I8: =500/1000 -> 0.5 | J8: =0 -> 0 | K8: =SUM(Tabela2[[#This Row],[Bond]:[Financial Letter]]) -> 8.1122

Sheet Planilha5
A1: year | B1: type | C1: volume | D1: volume_r
A2: 2015 | B2: Bonds | C2: =549.45/1000 -> 0.54945 | D2: {=C2/_xlfn._xlws.FILTER(Planilha9!$D$2:$D$8,(Planilha9!$A$2:$A$8)=A2)} -> 0.54945
A3: 2015 | B3: Agribusiness Credit Receivable Certificates (CRA) | C3: 0 | D3: {=C3/_xlfn._xlws.FILTER(Planilha9!$D$2:$D$8,(Planilha9!$A$2:$A$8)=A3)} -> 0
A4: 2015 | B4: Real Estate Receivables Certificates (CRI) | C4: 0 | D4: {=C4/_xlfn._xlws.FILTER(Planilha9!$D$2:$D$8,(Planilha9!$A$2:$A$8)=A4)} -> 0
A5: 2015 | B5: Debentures | C5: 0 | D5: {=C5/_xlfn._xlws.FILTER(Planilha9!$D$2:$D$8,(Planilha9!$A$2:$A$8)=A5)} -> 0
A6: 2015 | B6: Infrastructure Debentures | C6: 0 | D6: {=C6/_xlfn._xlws.FILTER(Planilha9!$D$2:$D$8,(Planilha9!$A$2:$A$8)=A6)} -> 0
A7: 2015 | B7: Loans | C7: 0 | D7: {=C7/_xlfn._xlws.FILTER(Planilha9!$D$2:$D$8,(Planilha9!$A$2:$A$8)=A7)} -> 0
A8: 2015 | B8: Credit Receivables Investment Funds (FIDC) | C8: 0 | D8: {=C8/_xlfn._xlws.FILTER(Planilha9!$D$2:$D$8,(Planilha9!$A$2:$A$8)=A8)} -> 0
A9: 2015 | B9: Global Notes | C9: 0 | D9: {=C9/_xlfn._xlws.FILTER(Planilha9!$D$2:$D$8,(Planilha9!$A$2:$A$8)=A9)} -> 0
A10: 2015 | B10: Financial Letters | C10: 0 | D10: {=C10/_xlfn._xlws.FILTER(Planilha9!$D$2:$D$8,(Planilha9!$A$2:$A$8)=A10)} -> 0
A11: 2016 | B11: Bonds | C11: =700/1000 -> 0.7 | D11: {=C11/_xlfn._xlws.FILTER(Planilha9!$D$2:$D$8,(Planilha9!$A$2:$A$8)=A11)} -> 0.69420271
A12: 2016 | B12: Agribusiness Credit Receivable Certificates (CRA) | C12: =291.77/1000 -> 0.29177 | D12: {=C12/_xlfn._xlws.FILTER(Planilha9!$D$2:$D$8,(Planilha9!$A$2:$A$8)=A12)} -> 0.28935361
A13: 2016 | B13: Real Estate Receivables Certificates (CRI) | C13: =0 -> 0 | D13: {=C13/_xlfn._xlws.FILTER(Planilha9!$D$2:$D$8,(Planilha9!$A$2:$A$8)=A13)} -> 0
A14: 2016 | B14: Debentures | C14: =61.6/1000 -> 0.0616 | D14: {=C14/_xlfn._xlws.FILTER(Planilha9!$D$2:$D$8,(Planilha9!$A$2:$A$8)=A14)} -> 0.061089839
A15: 2016 | B15: Infrastructure Debentures | C15: =0 -> 0 | D15: {=C15/_xlfn._xlws.FILTER(Planilha9!$D$2:$D$8,(Planilha9!$A$2:$A$8)=A15)} -> 0
A16: 2016 | B16: Loans | C16: =0 -> 0 | D16: {=C16/_xlfn._xlws.FILTER(Planilha9!$D$2:$D$8,(Planilha9!$A$2:$A$8)=A16)} -> 0
A17: 2016 | B17: Credit Receivables Investment Funds (FIDC) | C17: =0 -> 0 | D17: {=C17/_xlfn._xlws.FILTER(Planilha9!$D$2:$D$8,(Planilha9!$A$2:$A$8)=A17)} -> 0
A18: 2016 | B18: Global Notes | C18: =0 -> 0 | D18: {=C18/_xlfn._xlws.FILTER(Planilha9!$D$2:$D$8,(Planilha9!$A$2:$A$8)=A18)} -> 0
A19: 2016 | B19: Financial Letters | C19: =0 -> 0 | D19: {=C19/_xlfn._xlws.FILTER(Planilha9!$D$2:$D$8,(Planilha9!$A$2:$A$8)=A19)} -> 0
A20: 2017 | B20: Bonds | C20: =(700+1000+500)/1000 -> 2.2 | D20: {=C20/_xlfn._xlws.FILTER(Planilha9!$D$2:$D$8,(Planilha9!$A$2:$A$8)=A20)} -> 2.144889
A21: 2017 | B21: Agribusiness Credit Receivable Certificates (CRA) | C21: =0 -> 0 | D21: {=C21/_xlfn._xlws.FILTER(Planilha9!$D$2:$D$8,(Planilha9!$A$2:$A$8)=A21)} -> 0
A22: 2017 | B22: Real Estate Receivables Certificates (CRI) | C22: =0 -> 0 | D22: {=C22/_xlfn._xlws.FILTER(Planilha9!$D$2:$D$8,(Planilha9!$A$2:$A$8)=A22)} -> 0
A23: 2017 | B23: Debentures | C23: =0 -> 0 | D23: {=C23/_xlfn._xlws.FILTER(Planilha9!$D$2:$D$8,(Planilha9!$A$2:$A$8)=A23)} -> 0
A24: 2017 | B24: Infrastructure Debentures | C24: =(13.28+34.06+69.62+14.67+3.39+3.24)/1000 -> 0.13826 | D24: {=C24/_xlfn._xlws.FILTER(Planilha9!$D$2:$D$8,(Planilha9!$A$2:$A$8)=A24)} -> 0.13479652
A25: 2017 | B25: Loans | C25: =0 -> 0 | D25: {=C25/_xlfn._xlws.FILTER(Planilha9!$D$2:$D$8,(Planilha9!$A$2:$A$8)=A25)} -> 0
A26: 2017 | B26: Credit Receivables Investment Funds (FIDC) | C26: =0 -> 0 | D26: {=C26/_xlfn._xlws.FILTER(Planilha9!$D$2:$D$8,(Planilha9!$A$2:$A$8)=A26)} -> 0
A27: 2017 | B27: Global Notes | C27: =0 -> 0 | D27: {=C27/_xlfn._xlws.FILTER(Planilha9!$D$2:$D$8,(Planilha9!$A$2:$A$8)=A27)} -> 0
A28: 2017 | B28: Financial Letters | C28: =0 -> 0 | D28: {=C28/_xlfn._xlws.FILTER(Planilha9!$D$2:$D$8,(Planilha9!$A$2:$A$8)=A28)} -> 0
A29: 2018 | B29: Bonds | C29: =0 -> 0 | D29: {=C29/_xlfn._xlws.FILTER(Planilha9!$D$2:$D$8,(Planilha9!$A$2:$A$8)=A29)} -> 0
A30: 2018 | B30: Agribusiness Credit Receivable Certificates (CRA) | C30: =0 -> 0 | D30: {=C30/_xlfn._xlws.FILTER(Planilha9!$D$2:$D$8,(Planilha9!$A$2:$A$8)=A30)} -> 0
A31: 2018 | B31: Real Estate Receivables Certificates (CRI) | C31: =0 -> 0 | D31: {=C31/_xlfn._xlws.FILTER(Planilha9!$D$2:$D$8,(Planilha9!$A$2:$A$8)=A31)} -> 0
A32: 2018 | B32: Debentures | C32: =(1.51+9.82)/1000 -> 0.01133 | D32: {=C32/_xlfn._xlws.FILTER(Planilha9!$D$2:$D$8,(Planilha9!$A$2:$A$8)=A32)} -> 0.010729704
A33: 2018 | B33: Infrastructure Debentures | C33: =(181.28+31.38)/1000 -> 0.21266 | D33: {=C33/_xlfn._xlws.FILTER(Planilha9!$D$2:$D$8,(Planilha9!$A$2:$A$8)=A33)} -> 0.20139266
A34: 2018 | B34: Loans | C34: =0 -> 0 | D34: {=C34/_xlfn._xlws.FILTER(Planilha9!$D$2:$D$8,(Planilha9!$A$2:$A$8)=A34)} -> 0
A35: 2018 | B35: Credit Receivables Investment Funds (FIDC) | C35: =0 -> 0 | D35: {=C35/_xlfn._xlws.FILTER(Planilha9!$D$2:$D$8,(Planilha9!$A$2:$A$8)=A35)} -> 0
A36: 2018 | B36: Global Notes | C36: =0 -> 0 | D36: {=C36/_xlfn._xlws.FILTER(Planilha9!$D$2:$D$8,(Planilha9!$A$2:$A$8)=A36)} -> 0
A37: 2018 | B37: Financial Letters | C37: =0 -> 0 | D37: {=C37/_xlfn._xlws.FILTER(Planilha9!$D$2:$D$8,(Planilha9!$A$2:$A$8)=A37)} -> 0
A38: 2019 | B38: Bonds | C38: =(500+500)/1000 -> 1 | D38: {=C38/_xlfn._xlws.FILTER(Planilha9!$D$2:$D$8,(Planilha9!$A$2:$A$8)=A38)} -> 0.93016748
A39: 2019 | B39: Agribusiness Credit Receivable Certificates (CRA) | C39: =9.65/1000 -> 0.00965 | D39: {=C39/_xlfn._xlws.FILTER(Planilha9!$D$2:$D$8,(Planilha9!$A$2:$A$8)=A39)} -> 0.0089761162
A40: 2019 | B40: Real Estate Receivables Certificates (CRI) | C40: =4.49/1000 -> 0.00449 | D40: {=C40/_xlfn._xlws.FILTER(Planilha9!$D$2:$D$8,(Planilha9!$A$2:$A$8)=A40)} -> 0.004176452
...

Sheet Planilha6
A1: year | B1: total | C1: total_r
A2: 2015 | B2: =SUM(Tabela2[[#This Row],[Bond]:[Financial Letter]]) -> 0.54945 | C2: {=B2/_xlfn._xlws.FILTER(Planilha9!$D$2:$D$8,(Planilha9!$A$2:$A$8)=A2)} -> 0.54945
A3: 2016 | B3: =SUM(Tabela2[[#This Row],[Bond]:[Financial Letter]]) -> 1.05337 | C3: {=B3/_xlfn._xlws.FILTER(Planilha9!$D$2:$D$8,(Planilha9!$A$2:$A$8)=A3)} -> 1.0446462
A4: 2017 | B4: =SUM(Tabela2[[#This Row],[Bond]:[Financial Letter]]) -> 2.33826 | C4: {=B4/_xlfn._xlws.FILTER(Planilha9!$D$2:$D$8,(Planilha9!$A$2:$A$8)=A4)} -> 2.2796855
A5: 2018 | B5: =SUM(Tabela2[[#This Row],[Bond]:[Financial Letter]]) -> 0.22399 | C5: {=B5/_xlfn._xlws.FILTER(Planilha9!$D$2:$D$8,(Planilha9!$A$2:$A$8)=A5)} -> 0.21212237
A6: 2019 | B6: =SUM(Tabela2[[#This Row],[Bond]:[Financial Letter]]) -> 2.50938 | C6: {=B6/_xlfn._xlws.FILTER(Planilha9!$D$2:$D$8,(Planilha9!$A$2:$A$8)=A6)} -> 2.3341437
A7: 2020 | B7: =SUM(Tabela2[[#This Row],[Bond]:[Financial Letter]]) -> 5.30385 | C7: {=B7/_xlfn._xlws.FILTER(Planilha9!$D$2:$D$8,(Planilha9!$A$2:$A$8)=A7)} -> 4.8852958
A8: 2021 | B8: =SUM(Tabela2[[#This Row],[Bond]:[Financial Letter]]) -> 8.1122 | C8: {=B8/_xlfn._xlws.FILTER(Planilha9!$D$2:$D$8,(Planilha9!$A$2:$A$8)=A8)} -> 7.0915301

Sheet Planilha7
A1: year | B1: type | C1: volume | D1: volume_r
A2: 2015 | B2: Non-financial corporate | C2: 0.5495 | D2: {=C2/_xlfn._xlws.FILTER(Planilha9!$D$2:$D$8,(Planilha9!$A$2:$A$8)=A2)} -> 0.5495
A3: 2015 | B3: State-owned enterprise | C3: 0 | D3: {=C3/_xlfn._xlws.FILTER(Planilha9!$D$2:$D$8,(Planilha9!$A$2:$A$8)=A3)} -> 0
A4: 2015 | B4: Financial corporate | C4: 0 | D4: {=C4/_xlfn._xlws.FILTER(Planilha9!$D$2:$D$8,(Planilha9!$A$2:$A$8)=A4)} -> 0
A5: 2016 | B5: Non-financial corporate | C5: 1.05337 | D5: {=C5/_xlfn._xlws.FILTER(Planilha9!$D$2:$D$8,(Planilha9!$A$2:$A$8)=A5)} -> 1.0446462
A6: 2016 | B6: State-owned enterprise | C6: 0 | D6: {=C6/_xlfn._xlws.FILTER(Planilha9!$D$2:$D$8,(Planilha9!$A$2:$A$8)=A6)} -> 0
A7: 2016 | B7: Financial corporate | C7: 0 | D7: {=C7/_xlfn._xlws.FILTER(Planilha9!$D$2:$D$8,(Planilha9!$A$2:$A$8)=A7)} -> 0
A8: 2017 | B8: Non-financial corporate | C8: 1.33826 | D8: {=C8/_xlfn._xlws.FILTER(Planilha9!$D$2:$D$8,(Planilha9!$A$2:$A$8)=A8)} -> 1.304736
A9: 2017 | B9: State-owned enterprise | C9: 1 | D9: {=C9/_xlfn._xlws.FILTER(Planilha9!$D$2:$D$8,(Planilha9!$A$2:$A$8)=A9)} -> 0.97494955
A10: 2017 | B10: Financial corporate | C10: 0 | D10: {=C10/_xlfn._xlws.FILTER(Planilha9!$D$2:$D$8,(Planilha9!$A$2:$A$8)=A10)} -> 0
A11: 2018 | B11: Non-financial corporate | C11: 0.22399 | D11: {=C11/_xlfn._xlws.FILTER(Planilha9!$D$2:$D$8,(Planilha9!$A$2:$A$8)=A11)} -> 0.21212237
A12: 2018 | B12: State-owned enterprise | C12: 0 | D12: {=C12/_xlfn._xlws.FILTER(Planilha9!$D$2:$D$8,(Planilha9!$A$2:$A$8)=A12)} -> 0
A13: 2018 | B13: Financial corporate | C13: 0 | D13: {=C13/_xlfn._xlws.FILTER(Planilha9!$D$2:$D$8,(Planilha9!$A$2:$A$8)=A13)} -> 0
... A22: 2021 | B22: Financial corporate | C22: 1 | D22: {=C22/_xlfn._xlws.FILTER(Planilha9!$D$2:$D$8,(Planilha9!$A$2:$A$8)=A22)} -> 0.87418087

Sheet Planilha8
A1: year | B1: type | C1: volume | D1: volume_r
A2: 2015 | B2: Agricultural | C2: 0 | D2: {=C2/_xlfn._xlws.FILTER(Planilha9!$D$2:$D$8,(Planilha9!$A$2:$A$8)=A2)} -> 0
A3: 2015 | B3: Energy storage | C3: 0 | D3: {=C3/_xlfn._xlws.FILTER(Planilha9!$D$2:$D$8,(Planilha9!$A$2:$A$8)=A3)} -> 0
A4: 2015 | B4: Bioenergy | C4: 0 | D4: {=C4/_xlfn._xlws.FILTER(Planilha9!$D$2:$D$8,(Planilha9!$A$2:$A$8)=A4)} -> 0
A5: 2015 | B5: Performance | C5: 0 | D5: {=C5/_xlfn._xlws.FILTER(Planilha9!$D$2:$D$8,(Planilha9!$A$2:$A$8)=A5)} -> 0
A6: 2015 | B6: Eco-efficiency | C6: 0.54945 | D6: {=C6/_xlfn._xlws.FILTER(Planilha9!$D$2:$D$8,(Planilha9!$A$2:$A$8)=A6)} -> 0.54945
A7: 2015 | B7: Energy efficiency | C7: 0 | D7: {=C7/_xlfn._xlws.FILTER(Planilha9!$D$2:$D$8,(Planilha9!$A$2:$A$8)=A7)} -> 0
A8: 2015 | B8: Renewable energy | C8: 0 | D8: {=C8/_xlfn._xlws.FILTER(Planilha9!$D$2:$D$8,(Planilha9!$A$2:$A$8)=A8)} -> 0
A9: 2015 | B9: Forests | C9: 0 | D9: {=C9/_xlfn._xlws.FILTER(Planilha9!$D$2:$D$8,(Planilha9!$A$2:$A$8)=A9)} -> 0
A10: 2015 | B10: Popular housing | C10: 0 | D10: {=C10/_xlfn._xlws.FILTER(Planilha9!$D$2:$D$8,(Planilha9!$A$2:$A$8)=A10)} -> 0
A11: 2015 | B11: Micro, small and medium enterprises | C11: 0 | D11: {=C11/_xlfn._xlws.FILTER(Planilha9!$D$2:$D$8,(Planilha9!$A$2:$A$8)=A11)} -> 0
A12: 2015 | B12: Multiples | C12: 0 | D12: {=C12/_xlfn._xlws.FILTER(Planilha9!$D$2:$D$8,(Planilha9!$A$2:$A$8)=A12)} -> 0
A13: 2015 | B13: Sanitation | C13: 0 | D13: {=C13/_xlfn._xlws.FILTER(Planilha9!$D$2:$D$8,(Planilha9!$A$2:$A$8)=A13)} -> 0
... A99: 2021 | B99: Transportation | C99: 0.23077 | D99: {=C99/_xlfn._xlws.FILTER(Planilha9!$D$2:$D$8,(Planilha9!$A$2:$A$8)=A99)} -> 0.20173472

Sheet Planilha9
A1: year | B1: cpi | C1: number_index | D1: index
A2: 2015 | B2: 238.654 | C2: 100 | D2: =C2/100 -> 1
A3: 2016 | B3: 240.647 | C3: =((B3-$B$2)/$B$2)*100+$C$2 -> 100.8351 | D3: =C3/100 -> 1.008351
A4: 2017 | B4: 244.786 | C4: =((B4-$B$2)/$B$2)*100+$C$2 -> 102.56941 | D4: =C4/100 -> 1.0256941
A5: 2018 | B5: 252.006 | C5: =((B5-$B$2)/$B$2)*100+$C$2 -> 105.59471 | D5: =C5/100 -> 1.0559471
A6: 2019 | B6: 256.571 | C6: =((B6-$B$2)/$B$2)*100+$C$2 -> 107.50752 | D6: =C6/100 -> 1.0750752
A7: 2020 | B7: 259.101 | C7: =((B7-$B$2)/$B$2)*100+$C$2 -> 108.56763 | D7: =C7/100 -> 1.0856763
A8: 2021 | B8: 273.003 | C8: =((B8-$B$2)/$B$2)*100+$C$2 -> 114.3928 | D8: =C8/100 -> 1.143928
